Workbook

Sheet Instructions
A1: AI CFO ROI Model (Template)
A3: How to use this workbook:
B4: 1) Go to the Inputs sheet and fill blue cells (assumptions). Yellow-highlighted inputs are the most important.
B5: 2) In UseCases, fill the blue inputs for each use case you plan to include. Leave unused use cases blank (0 values).
B6: 3) In Costs, enter one-time and run costs (blue).
B7: 4) Summary automatically calculates benefits, net value, ROI, payback and 3-year NPV (if discount rate is provided).
B9: Conventions:
B10: - Blue text = inputs you should change
B11: - Black text = formulas / calculated fields
B12: - Green text = links to other sheets
B13: - Yellow fill = key assumptions needing attention
B15: Tip: Keep forecasting ROI conservative unless you can tie accuracy to a specific decision lever (hiring, inventory, spend, borrowing).

Sheet Inputs
A1: Global assumptions
A3: Currency label (for display) | B3: USD
A4: Fully loaded hourly cost | B4: 75
A5: Cost of capital / interest rate (annual) | B5: 0.1
A6: Discount rate for NPV (annual) | B6: 0.1
A7: Working days per year (for daily reporting conversion) | B7: 260
A9: Default confidence factors (used if you link cells in UseCases)
A10: Adoption factor (A) | B10: 0.75
A11: Performance factor (P) | B11: 0.8
A12: Realization rate (time savings to £) | B12: 0.5
A13: Probability of acting on forecast insight | B13: 0.6
A15: Scenario multipliers (for quick downside/base/upside)
A16: Scenario | B16: Benefit multiplier | C16: Cost multiplier
A17: Downside | B17: 0.7 | C17: 1.2
A18: Base | B18: 1 | C18: 1
A19: Upside | B19: 1.2 | C19: 0.9

Sheet UseCases
A1: Use case inputs (blue) and calculated benefits (black)
A2: Item | B2: Input | C2: Unit/Notes | D2: Year 1 | E2: Year 2 | F2: Year 3
A3: Hourly cost (linked) | B3: =Inputs!$B$4 -> 75 | C3: Pulls from Inputs
A4: Cost of capital (linked) | B4: =Inputs!$B$5 -> 0.1 | C4: Pulls from Inputs
A5: Default Adoption (linked) | B5: =Inputs!$B$9 -> 0 | C5: Pulls from Inputs
A6: Default Performance (linked) | B6: =Inputs!$B$10 -> 0.75 | C6: Pulls from Inputs
A7: Default Realization (linked) | B7: =Inputs!$B$11 -> 0.8 | C7: Pulls from Inputs
A8: Default Prob. of acting (linked) | B8: =Inputs!$B$12 -> 0.5 | C8: Pulls from Inputs
A9: 1) Daily reporting (time savings)
A10: Hours per reporting cycle | B10: 3 | C10: hours
A11: Cycles per year | B11: 260 | C11: e.g., 260 business days
A12: % time reduction from AI | B12: 0.25 | C12: fraction (25% = 0.25)
A13: Realization rate (time→£) | B13: =B7 -> 0.8 | C13: use linked default or overwrite
A14: Adoption factor (A) | B14: =B5 -> 0 | C14: use linked default or overwrite
A15: Performance factor (P) | B15: =B6 -> 0.75 | C15: use linked default or overwrite
A16: Ramp to full benefit (Y1/Y2/Y3) | B16: 0.5 | C16: Y1 ramp fraction; adjust on right columns | D16: 0.5 | E16: 1 | F16: 1
A17: Expected benefit | C17: currency / year | D17: =(B10*B11*B12*B3)*B13*B14*B15*D16 -> 0 | E17: =(B10*B11*B12*B3)*B13*B14*B15*E16 -> 0 | F17: =(B10*B11*B12*B3)*B13*B14*B15*F16 -> 0
A18: 2) Close automation (time + contractor/overtime savings)
A19: Finance hours per close | B19: 320 | C19: hours
A20: Closes per year | B20: 12 | C20: typically 12
A21: % time reduction from AI | B21: 0.2 | C21: fraction
A22: Contractor/overtime spend per year | B22: 60000 | C22: hard savings opportunity
A23: % reduction in contractor/overtime | B23: 0.3 | C23: fraction
A24: Realization rate (time→£) | B24: =B7 -> 0.8 | C24: use linked default or overwrite
A25: Adoption factor (A) | B25: =B5 -> 0 | C25: use linked default or overwrite
A26: Performance factor (P) | B26: =B6 -> 0.75 | C26: use linked default or overwrite
A27: Ramp to full benefit (Y1/Y2/Y3) | B27: 0.6 | C27: Y1 ramp fraction; adjust on right columns | D27: 0.6 | E27: 1 | F27: 1
A28: Expected benefit | C28: currency / year | D28: =((B19*B20*B21*B3)*B24+(B22*B23))*B25*B26*D27 -> 0 | E28: =((B19*B20*B21*B3)*B24+(B22*B23))*B25*B26*E27 -> 0 | F28: =((B19*B20*B21*B3)*B24+(B22*B23))*B25*B26*F27 -> 0
A29: 3) Forecasting (monetize via decision lever)
A30: Baseline forecast error (MAPE) | B30: 0.12 | C30: fraction
A31: Target forecast error (MAPE) | B31: 0.08 | C31: fraction
A32: Financial sensitivity | B32: 500000 | C32: £ per 1.00 (100%) error; see note
A33: Probability of acting on insight | B33: =B8 -> 0.5 | C33: use linked default or overwrite
A34: Adoption factor (A) | B34: =B5 -> 0 | C34: use linked default or overwrite
A35: Performance factor (P) | B35: =B6 -> 0.75 | C35: use linked default or overwrite
A36: Ramp to full benefit (Y1/Y2/Y3) | B36: 0.4 | C36: Y1 ramp fraction; adjust on right columns | D36: 0.4 | E36: 0.8 | F36: 1
A37: Expected benefit | C37: currency / year | D37: =MAX(0,(B30-B31))*B32*B33*B34*B35*D36 -> 0 | E37: =MAX(0,(B30-B31))*B32*B33*B34*B35*E36 -> 0 | F37: =MAX(0,(B30-B31))*B32*B33*B34*B35*F36 -> 0
A38: 4) Inventory (cash + write-downs + expediting)
A39: Annual COGS | B39: 20000000 | C39: currency / year
A40: DIO reduction (days) | B40: 5 | C40: days
...

Sheet Costs
A1: Costs (blue inputs)
A2: Cost item | B2: One-time | C2: Year 1 | D2: Year 2 | E2: Year 3
A3: Implementation / onboarding services | B3: 0
A4: Integrations / ETL / iPaaS work | B4: 0
A5: Data mapping & cleanup effort | B5: 0
A6: Security / legal / compliance | B6: 0
A7: Internal SMEs (finance, IT, data) - converted to £ | B7: 0
A8: Change management & training | B8: 0
A9: Run costs (annual)
A10: Subscription / licenses | C10: 0 | D10: 0 | E10: 0
A11: Cloud compute (if applicable) | C11: 0 | D11: 0 | E11: 0
A12: Support / admin | C12: 0 | D12: 0 | E12: 0
A13: Monitoring / governance | C13: 0 | D13: 0 | E13: 0
A14: Ongoing improvements | C14: 0 | D14: 0 | E14: 0
A15: TOTAL costs | B15: =SUM(B3:B13) -> 0 | C15: =SUM(C10:C14) -> 0 | D15: =SUM(D10:D14) -> 0 | E15: =SUM(E10:E14) -> 0

Sheet Summary
A1: Summary (Expected case)
A2: Metric | B2: One-time | C2: Year 1 | D2: Year 2 | E2: Year 3
A3: Total expected benefits | C3: =UseCases!D71 -> 0 | D3: =UseCases!E71 -> 0 | E3: =UseCases!F71 -> 0
A4: Total costs | B4: =Costs!B15 -> 0 | C4: =Costs!C15 -> 0 | D4: =Costs!D15 -> 0 | E4: =Costs!E15 -> 0
A5: Net benefit | C5: =C3-C4 -> 0 | D5: =D3-D4 -> 0 | E5: =E3-E4 -> 0
A7: ROI (Year 1 net / one-time)
A8: ROI | B8: =IF(B4=0,"",C5/B4)
A9: Payback (months) (approx, using Year 1 net / 12) | B9: =IF(B4=0,"",B4/(C5/12))
A10: 3-year NPV (discounted net benefits - one-time) | B10: =IF(B4=0,"",-B4 + C5/(1+Inputs!B6)^1 + D5/(1+Inputs!B6)^2 + E5/(1+Inputs!B6)^3)
A12: Scenario view (multipliers from Inputs)
A13: Scenario | B13: Benefit x | C13: Cost x | D13: ROI (Year 1)
A14: =Inputs!A17 -> Downside | B14: =Inputs!B17 -> 0.7 | C14: =Inputs!C17 -> 1.2 | D14: =IF(Costs!B15=0,"",((UseCases!D71*B14 - Costs!C15*C14)/(Costs!B15*C14)))
A15: =Inputs!A18 -> Base | B15: =Inputs!B18 -> 1 | C15: =Inputs!C18 -> 1 | D15: =IF(Costs!B15=0,"",((UseCases!D71*B15 - Costs!C15*C15)/(Costs!B15*C15)))
A16: =Inputs!A19 -> Upside | B16: =Inputs!B19 -> 1.2 | C16: =Inputs!C19 -> 0.9 | D16: =IF(Costs!B15=0,"",((UseCases!D71*B16 - Costs!C15*C16)/(Costs!B15*C16)))

Sheet DataRequest
A1: Client data request checklist (for credible ROI)
A3: Category | B3: What to ask for (anonymized ok)
A4: Daily reporting | B4: List of recurring reports; who produces them; time per report; cadence; rework/correction rate.
A5: Close | B5: Close calendar; hours by role; reconciliation count; manual journals; overtime/contractor spend; post-close adjustments/errors.
A6: Forecasting | B6: Actual vs forecast history (12–24 months) for revenue, GM, opex, cash; key drivers; decisions the forecast drives; baseline forecast accuracy.
A7: Inventory | B7: COGS; DIO; stockouts + expedite spend; obsolescence/write-downs; service level targets; key SKUs/product hierarchy.
A8: Working capital | B8: DSO/DPO history; AR aging; bad debt/write-offs; borrowing levels + rates; cash policy; collection process notes.
A9: Board pack | B9: Time to produce pack; number of iterations; sample pack (redacted); KPI definitions and narrative style expectations.
A10: Security / compliance | B10: SSO/RBAC needs; data residency; audit trail expectations; write-back approvals; regulated data categories.
